<?xml version='1.0' encoding='utf-8'?>
<sdf version="1.6">
  <model name="gpr">
    <static>false</static>

    <!-- Platform +++++++++++++++++++++++++++++++++++++ -->

    <!-- Chassis -->
    <link name="base_link">
      <pose frame="">0 0 0 0 0 0</pose>

      <gravity>true</gravity>
      <self_collide>false</self_collide>
      <enable_wind>false</enable_wind>
      <kinematic>false</kinematic>

      <inertial>
        <mass>46.064</mass>
        <inertia>
          <ixx>0.615397</ixx>
          <ixy>-0.0240585</ixy>
          <ixz>-0.120749</ixz>
          <iyy>1.75388</iyy>
          <iyz>-0.0028322</iyz>
          <izz>2.03641</izz>
        </inertia>
      </inertial>

      <!-- Motors -->
      <collision name="motor_rear_left_collision">
        <pose>0.56092 0.20875 -0.38671 1.5708 0 0</pose>
        <geometry>
          <cylinder>
            <radius>0.0525</radius>
            <length>0.14465</length>
          </cylinder>
        </geometry>
      </collision>
      <visual name="motor_rear_left_visual">
        <pose>0.56092 0.20875 -0.38671 1.5708 0 0</pose>
        <geometry>
          <cylinder>
            <radius>0.0525</radius>
            <length>0.14465</length>
          </cylinder>
        </geometry>
        <material>
          <ambient>0.5 0 0 1</ambient>
          <diffuse>0.5 0 0 1</diffuse>
          <specular>0.5 0 0 1</specular>
        </material>
      </visual>
      <collision name="motor_rear_right_collision">
        <pose>0.56092 -0.20875 -0.38671 1.5708 0 0</pose>
        <geometry>
          <cylinder>
            <radius>0.0525</radius>
            <length>0.14465</length>
          </cylinder>
        </geometry>
      </collision>
      <visual name="motor_rear_right_visual">
        <pose>0.56092 -0.20875 -0.38671 1.5708 0 0</pose>
        <geometry>
          <cylinder>
            <radius>0.0525</radius>
            <length>0.14465</length>
          </cylinder>
        </geometry>
        <material>
          <ambient>0.5 0 0 1</ambient>
          <diffuse>0.5 0 0 1</diffuse>
          <specular>0.5 0 0 1</specular>
        </material>
      </visual>
      <collision name="motor_back_left_collision">
        <pose>-0.56092 0.20875 -0.38671 1.5708 0 0</pose>
        <geometry>
          <cylinder>
            <radius>0.0525</radius>
            <length>0.14465</length>
          </cylinder>
        </geometry>
      </collision>
      <visual name="motor_back_left_visual">
        <pose>-0.56092 0.20875 -0.38671 1.5708 0 0</pose>
        <geometry>
          <cylinder>
            <radius>0.0525</radius>
            <length>0.14465</length>
          </cylinder>
        </geometry>
        <material>
          <ambient>0.5 0 0 1</ambient>
          <diffuse>0.5 0 0 1</diffuse>
          <specular>0.5 0 0 1</specular>
        </material>
      </visual>
      <collision name="motor_back_right_collision">
        <pose>-0.56092 -0.20875 -0.38671 1.5708 0 0</pose>
        <geometry>
          <cylinder>
            <radius>0.0525</radius>
            <length>0.14465</length>
          </cylinder>
        </geometry>
      </collision>
      <visual name="motor_back_right_visual">
        <pose>-0.56092 -0.20875 -0.38671 1.5708 0 0</pose>
        <geometry>
          <cylinder>
            <radius>0.0525</radius>
            <length>0.14465</length>
          </cylinder>
        </geometry>
        <material>
          <ambient>0.5 0 0 1</ambient>
          <diffuse>0.5 0 0 1</diffuse>
          <specular>0.5 0 0 1</specular>
        </material>
      </visual>

      <!-- Frame -->
      <collision name="frame_rear_left_collision">
        <pose>-0.44757 0.22456 -0.37413 0 -1.13446 0</pose>
        <geometry>
          <box>
            <size>0.22860 0.031 0.062</size>
          </box>
        </geometry>
      </collision>
      <visual name="frame_rear_left_visual">
        <pose>-0.44757 0.22456 -0.37413 0 -1.13446 0</pose>
        <geometry>
          <box>
            <size>0.22860 0.031 0.062</size>
          </box>
        </geometry>
        <material>
          <ambient>0.5 0 0 1</ambient>
          <diffuse>0.5 0 0 1</diffuse>
          <specular>0.5 0 0 1</specular>
        </material>
      </visual>
      <collision name="frame_rear_right_collision">
        <pose>-0.44757 -0.22456 -0.37413 0 -1.13446 0</pose>
        <geometry>
          <box>
            <size>0.22860 0.031 0.062</size>
          </box>
        </geometry>
      </collision>
      <visual name="frame_rear_right_visual">
        <pose>-0.44757 -0.22456 -0.37413 0 -1.13446 0</pose>
        <geometry>
          <box>
            <size>0.22860 0.031 0.062</size>
          </box>
        </geometry>
        <material>
          <ambient>0.5 0 0 1</ambient>
          <diffuse>0.5 0 0 1</diffuse>
          <specular>0.5 0 0 1</specular>
        </material>
      </visual>

      <!-- GPR -->
      <collision name="gpr_collision">
        <pose>0 0 -0.30602 0 0 0</pose>
        <geometry>
          <box>
            <size>0.60600 0.39400 0.18830</size>
          </box>
        </geometry>
      </collision>
      <visual name="gpr__visual">
        <pose>0 0 -0.30602 0 0 0</pose>
        <geometry>
          <box>
            <size>0.60600 0.39400 0.18830</size>
          </box>
        </geometry>
        <material>
          <ambient>0.5 0 0 1</ambient>
          <diffuse>0.5 0 0 1</diffuse>
          <specular>0.5 0 0 1</specular>
        </material>
      </visual>

      <!-- PV -->
      <!--
      <visual name="pv_left_visual">
        <pose>0 0.2667 0.22553 0 0 0</pose>
        <geometry>
          <box>
            <size>1.07188 0.53340 0.03505</size>
          </box>
        </geometry>
        <material>
          <diffuse> 0.8 0.8 0.8 0.25</diffuse>
          <specular>0.5 0.5 0.5 1</specular>
        </material>
      </visual>
      <visual name="pv_right_visual">
        <pose>0 -0.2667 0.22553 0 0 0</pose>
        <geometry>
          <box>
            <size>1.07188 0.53340 0.03505</size>
          </box>
        </geometry>
        <material>
          <diffuse> 0.8 0.8 0.8 0.25</diffuse>
          <specular>0.5 0.5 0.5 1</specular>
        </material>
      </visual>
      -->

      <!-- GPS -->
      <visual name="gps_visual">
        <pose>-0.58619 0.19456 0.66055 0 0 0</pose>
        <geometry>
          <cylinder>
            <radius>0.088</radius>
            <length>0.07</length>
          </cylinder>
        </geometry>
        <material>
          <ambient> 0.5 0.0 0.5 1</ambient>
          <diffuse> 0.5 0.0 0.5 1</diffuse>
          <specular>0.5 0.0 0.5 1</specular>
        </material>
      </visual>
      <visual name="gps_pole_visual">
        <pose>-0.58619 0.19456 0.25 0 0 0</pose>
        <geometry>
          <cylinder>
            <radius>0.02</radius>
            <length>1.0</length>
          </cylinder>
        </geometry>
        <material>
          <ambient> 0.5 0.0 0.5 1</ambient>
          <diffuse> 0.5 0.0 0.5 1</diffuse>
          <specular>0.5 0.0 0.5 1</specular>
        </material>
      </visual>

      <!-- Base -->
      <visual name="base_link_visual">
        <pose>0 0 0 1.5708 0 1.5708</pose>
        <geometry>
          <mesh>
            <scale>1 1 1</scale>
            <uri>meshes/chassis.stl</uri>
          </mesh>
        </geometry>
        <material>
          <ambient> 0.25 0.25 0.25 1</ambient>
          <diffuse> 0.25 0.25 0.25 1</diffuse>
          <specular>0.25 0.25 0.25 1</specular>
        </material>
      </visual>

    </link>

    <!-- Front left Wheel -->
    <link name="front_left_wheel_link">
      <pose>0.52294 0.35953 -0.40442 1.5708 0 0</pose>
      <gravity>true</gravity>
      <self_collide>false</self_collide>
      <enable_wind>false</enable_wind>
      <kinematic>false</kinematic>
      <inertial>
        <mass>2.637</mass>
        <inertia>
          <ixx>0.02467</ixx>
          <ixy>0</ixy>
          <ixz>0</ixz>
          <iyy>0.04411</iyy>
          <iyz>0</iyz>
          <izz>0.02467</izz>
        </inertia>
      </inertial>
      <collision name="collision">
        <pose>0 0 0 0 0 0</pose>
        <geometry>
          <cylinder>
            <length>0.10231</length>
            <radius>0.1651</radius>
          </cylinder>
        </geometry>
        <surface>
          <contact>
            <ode>
              <kp>1e+07</kp>
              <kd>1</kd>
            </ode>
          </contact>
          <friction>
            <ode>
              <mu>0.5</mu>
              <mu2>1</mu2>
              <slip1>0.00062</slip1>
              <slip2>0</slip2>
              <fdir1>0 0 1</fdir1>
            </ode>
          </friction>
        </surface>
      </collision>
      <visual name="visual">
        <pose>0 0 0 0 0 0</pose>
        <geometry>
          <mesh>
            <scale>1 1 1</scale>
            <uri>meshes/wheel.stl</uri>
          </mesh>
        </geometry>
        <material>
          <ambient> 0.02 0.02 0.02 1</ambient>
          <diffuse> 0.02 0.02 0.02 1</diffuse>
          <specular>0.02 0.02 0.02 1</specular>
        </material>
      </visual>
      <!--
      <visual name="collision_visual">
        <pose>0 0 0 0 0 0</pose>
        <geometry>
          <cylinder>
            <length>0.10231</length>
            <radius>0.1651</radius>
          </cylinder>
        </geometry>
        <material>
          <diffuse> 1.0 0.0 0.1 0.7</diffuse>
          <specular>0.5 0.5 0.5 1</specular>
        </material>
      </visual>
      -->
    </link>
    <joint name="front_left_wheel_joint" type="revolute">
      <child>front_left_wheel_link</child>
      <parent>base_link</parent>
      <axis>
        <xyz>0 1 0</xyz>
        <limit>
          <lower>-1e+16</lower>
          <upper>1e+16</upper>
        </limit>
        <dynamics>
          <spring_reference>0</spring_reference>
          <spring_stiffness>0</spring_stiffness>
        </dynamics>
        <use_parent_model_frame>1</use_parent_model_frame>
      </axis>
    </joint>

    <!-- Front right Wheel -->
    <link name="front_right_wheel_link">
      <pose>0.52294 -0.35953 -0.40442 1.5708 0 0</pose>
      <gravity>true</gravity>
      <self_collide>false</self_collide>
      <enable_wind>false</enable_wind>
      <kinematic>false</kinematic>
      <inertial>
        <mass>2.637</mass>
        <inertia>
          <ixx>0.02467</ixx>
          <ixy>0</ixy>
          <ixz>0</ixz>
          <iyy>0.04411</iyy>
          <iyz>0</iyz>
          <izz>0.02467</izz>
        </inertia>
      </inertial>
      <collision name="collision">
        <pose>0 0 0 0 0 0</pose>
        <geometry>
          <cylinder>
            <length>0.10231</length>
            <radius>0.1651</radius>
          </cylinder>
        </geometry>
        <surface>
          <contact>
            <ode>
              <kp>1e+07</kp>
              <kd>1</kd>
            </ode>
          </contact>
          <friction>
            <ode>
              <mu>0.5</mu>
              <mu2>1</mu2>
              <slip1>0.00062</slip1>
              <slip2>0</slip2>
              <fdir1>0 0 1</fdir1>
            </ode>
          </friction>
        </surface>
      </collision>
      <visual name="visual">
        <pose>0 0 0 0 0 0</pose>
        <geometry>
          <mesh>
            <scale>1 1 1</scale>
            <uri>meshes/wheel.stl</uri>
          </mesh>
        </geometry>
        <material>
          <ambient> 0.02 0.02 0.02 1</ambient>
          <diffuse> 0.02 0.02 0.02 1</diffuse>
          <specular>0.02 0.02 0.02 1</specular>
        </material>
      </visual>
      <!--
      <visual name="collision_visual">
        <pose>0 0 0 0 0 0</pose>
        <geometry>
          <cylinder>
            <length>0.10231</length>
            <radius>0.1651</radius>
          </cylinder>
        </geometry>
        <material>
          <diffuse> 1.0 0.0 0.1 0.7</diffuse>
          <specular>0.5 0.5 0.5 1</specular>
        </material>
      </visual>
    -->
    </link>
    <joint name="front_right_wheel_joint" type="revolute">
      <child>front_right_wheel_link</child>
      <parent>base_link</parent>
      <axis>
        <xyz>0 1 0</xyz>
        <limit>
          <lower>-1e+16</lower>
          <upper>1e+16</upper>
        </limit>
        <dynamics>
          <spring_reference>0</spring_reference>
          <spring_stiffness>0</spring_stiffness>
        </dynamics>
        <use_parent_model_frame>1</use_parent_model_frame>
      </axis>
    </joint>

    <!-- Rear left Wheel -->
    <link name="rear_left_wheel_link">
      <pose>-0.52294 0.35953 -0.40442 1.5708 0 0</pose>
      <gravity>true</gravity>
      <self_collide>false</self_collide>
      <enable_wind>false</enable_wind>
      <kinematic>false</kinematic>
      <inertial>
        <mass>2.637</mass>
        <inertia>
          <ixx>0.02467</ixx>
          <ixy>0</ixy>
          <ixz>0</ixz>
          <iyy>0.04411</iyy>
          <iyz>0</iyz>
          <izz>0.02467</izz>
        </inertia>
      </inertial>
      <collision name="collision">
        <pose>0 0 0 0 0 0</pose>
        <geometry>
          <cylinder>
            <length>0.10231</length>
            <radius>0.1651</radius>
          </cylinder>
        </geometry>
        <surface>
          <contact>
            <ode>
              <kp>1e+07</kp>
              <kd>1</kd>
            </ode>
          </contact>
          <friction>
            <ode>
              <mu>0.5</mu>
              <mu2>1</mu2>
              <slip1>0.00062</slip1>
              <slip2>0</slip2>
              <fdir1>0 0 1</fdir1>
            </ode>
          </friction>
        </surface>
      </collision>
      <visual name="visual">
        <pose>0 0 0 0 0 0</pose>
        <geometry>
          <mesh>
            <scale>1 1 1</scale>
            <uri>meshes/wheel.stl</uri>
          </mesh>
        </geometry>
        <material>
          <ambient> 0.02 0.02 0.02 1</ambient>
          <diffuse> 0.02 0.02 0.02 1</diffuse>
          <specular>0.02 0.02 0.02 1</specular>
        </material>
      </visual>
      <!--
      <visual name="collision_visual">
        <pose>0 0 0 0 0 0</pose>
        <geometry>
          <cylinder>
            <length>0.10231</length>
            <radius>0.1651</radius>
          </cylinder>
        </geometry>
        <material>
          <diffuse> 1.0 0.0 0.1 0.7</diffuse>
          <specular>0.5 0.5 0.5 1</specular>
        </material>
      </visual>
    -->
    </link>
    <joint name="rear_left_wheel_joint" type="revolute">
      <child>rear_left_wheel_link</child>
      <parent>base_link</parent>
      <axis>
        <xyz>0 1 0</xyz>
        <limit>
          <lower>-1e+16</lower>
          <upper>1e+16</upper>
        </limit>
        <dynamics>
          <spring_reference>0</spring_reference>
          <spring_stiffness>0</spring_stiffness>
        </dynamics>
        <use_parent_model_frame>1</use_parent_model_frame>
      </axis>
    </joint>

    <!-- Rear right Wheel -->
    <link name="rear_right_wheel_link">
      <pose>-0.52294 -0.35953 -0.40442 1.5708 0 0</pose>
      <gravity>true</gravity>
      <self_collide>false</self_collide>
      <enable_wind>false</enable_wind>
      <kinematic>false</kinematic>
      <inertial>
        <mass>2.637</mass>
        <inertia>
          <ixx>0.02467</ixx>
          <ixy>0</ixy>
          <ixz>0</ixz>
          <iyy>0.04411</iyy>
          <iyz>0</iyz>
          <izz>0.02467</izz>
        </inertia>
      </inertial>
      <collision name="collision">
        <pose>0 0 0 0 0 0</pose>
        <geometry>
          <cylinder>
            <length>0.10231</length>
            <radius>0.1651</radius>
          </cylinder>
        </geometry>
        <surface>
          <contact>
            <ode>
              <kp>1e+07</kp>
              <kd>1</kd>
            </ode>
          </contact>
          <friction>
            <ode>
              <mu>0.5</mu>
              <mu2>1</mu2>
              <slip1>0.00062</slip1>
              <slip2>0</slip2>
              <fdir1>0 0 1</fdir1>
            </ode>
          </friction>
        </surface>
      </collision>
      <visual name="visual">
        <pose>0 0 0 0 0 0</pose>
        <geometry>
          <mesh>
            <scale>1 1 1</scale>
            <uri>meshes/wheel.stl</uri>
          </mesh>
        </geometry>
        <material>
          <ambient> 0.02 0.02 0.02 1</ambient>
          <diffuse> 0.02 0.02 0.02 1</diffuse>
          <specular>0.02 0.02 0.02 1</specular>
        </material>
      </visual>
      <!--
      <visual name="collision_visual">
        <pose>0 0 0 0 0 0</pose>
        <geometry>
          <cylinder>
            <length>0.10231</length>
            <radius>0.1651</radius>
          </cylinder>
        </geometry>
        <material>
          <diffuse> 1.0 0.0 0.1 0.7</diffuse>
          <specular>0.5 0.5 0.5 1</specular>
        </material>
      </visual>
      -->
    </link>
    <joint name="rear_right_wheel_joint" type="revolute">
      <child>rear_right_wheel_link</child>
      <parent>base_link</parent>
      <axis>
        <xyz>0 1 0</xyz>
        <limit>
          <lower>-1e+16</lower>
          <upper>1e+16</upper>
        </limit>
        <dynamics>
          <spring_reference>0</spring_reference>
          <spring_stiffness>0</spring_stiffness>
        </dynamics>
        <use_parent_model_frame>1</use_parent_model_frame>
      </axis>
    </joint>

    <!-- Sensors +++++++++++++++++++++++++++++++++++++ -->

    <!-- Lidar -->
    <link name="lidar_link">
      <pose>0.62046 0 0.13303 0 0.50562677122 0</pose>
      <inertial>
        <mass>0.1</mass>
        <inertia>
          <ixx>0.000166667</ixx>
          <iyy>0.000166667</iyy>
          <izz>0.000166667</izz>
        </inertia>
      </inertial>
      <collision name="collision">
        <geometry>
          <cylinder>
            <radius>0.05</radius>
            <length>0.1</length>
          </cylinder>
        </geometry>
      </collision>
      <visual name="visual">
        <geometry>
          <cylinder>
            <radius>0.05</radius>
            <length>0.1</length>
          </cylinder>
        </geometry>
        <material>
          <ambient> 0.5 0.0 0.5 1</ambient>
          <diffuse> 0.5 0.0 0.5 1</diffuse>
          <specular>0.5 0.0 0.5 1</specular>
        </material>
      </visual>
      <sensor name='os1_32' type='gpu_lidar'>
        <topic>lidar</topic>
        <visualize>true</visualize>
        <always_on>true</always_on>
        <update_rate>10</update_rate>
        <lidar>
          <scan>
            <horizontal>
              <samples>1024</samples>
              <resolution>1</resolution>
              <min_angle>-1.396263</min_angle>
              <max_angle>1.396263</max_angle>
            </horizontal>
            <vertical>
              <samples>32</samples>
              <resolution>1</resolution>
              <min_angle>-0.261799</min_angle>
              <max_angle>0.261799</max_angle>
            </vertical>
          </scan>
          <range>
            <min>0.1</min>
            <max>120.0</max>
            <resolution>0.01</resolution>
          </range>
        </lidar>
      </sensor>
    </link>
    <joint name='lidar_joint' type='fixed'>
      <child>lidar_link</child>
      <parent>base_link</parent>
    </joint>

  </model>
</sdf>